Workbook

Sheet MACRO+watchlist+notes
A4: WATCHLIST | B4: top | C4: Debt | D4: 10yM | E4: d% change | G4: Region | H4: 10yM | I4: Indices | J4: 10yM | L4: Commodities | M4: 10yM | P4: Industries | Q4: 10yM | T4: Style | U4: 10yM | X4: Risk
B5: RK LOGO | C5: chart10y | D5: price | G5: chart10y | J5: price | K5: ch | L5: chart10y | P5: chart10y | T5: chart10y | X5: chart10y,M | Z5: port% | AA5: ticker | AB5: name | AC5: sector | AD5: industry | AE5: mkt cap | AF5: price | AG5: daily % change | AH5: 1m insider buying | AI5: 6m insider buying | AJ5: # of insiders | AK5: 6m val | AL5: % to val blend | AM5: % to 52w hi | AN5: % from 52w Lo | AO5: revs | AP5: s/p | AQ5: ebitda/ev | AR5: tb/p | AS5: b/p | AT5: e/p | AU5: cfo/p | AV5: sfcf/p | AW5: ncf/p | AX5: div/p | AY5: cash/p | AZ5: ncash/p | BA5: nn/p | BB5: asset/p | BC5: retear/mc | BD5: revs/debt | BE5: mc/ev
B6: DASH | C6: US Nom 5y/10y | G6: Vang US Stock Market | I6: S&P 500 | L6: Oil WTI | P6: Retail | T6: Russell1000 | X6: VIX
B7: Debt | C7: US Real 5y/10y | G7: S&P | I7: Dow | L7: Oil Brent | P7: Homebuilders | T7: Russell 2000 | X7: NYSE New Highs/Low
B8: Regin | C8: US 1-30y Treasuries | G8: All-World ex-US | I8: NASDAQ | L8: Natural Gas | P8: Homeconstruction | T8: Russell 3000 | X8: NYSE AD Line
B9: Indices | C9: US <1y Treasuries | G9: EAFE | I9: NASDAQ 100 QQQ | L9: Gold | P9: Consumer Goods | T9: S&P 500 | X9: NASDAQ AD Line
B10: Commodities | C10: US 1-3y Treasuries | G10: International | I10: Wilshire 5000 | L10: Silver | P10: Gaming | T10: S&P 500 =wght | X10: NYSE MCClellan Oscilator
B11: Industry | C11: US 7-10y Treasuries | G11: International SmallCap | I11: NYSE Composite | L11: Copper | P11: Aero & Defense | T11: S&P 400 | X11: NASDAQ McClellan
B12: Style | C12: US 20+y Treasuries | G12: Developed Markets | I12: Euronext 100 | L12: Palladium | P12: DJ Transports | T12: S&P 600 | X12: Put-Call
B13: risk | C13: US TIPS | G13: Emerging Mkts 1 | I13: Germany DAX | L13: Platinum | P13: Shipping | T13: Cambria Tall | X13: US 1-3y Treasuries
B14: RK Portfolio | C14: US Bond Market | G14: Emerging Mkts 2 | I14: London FTSE 100 | L14: Zinc | P14: Environmental Services | T14: S&P Dividend | X14: US 20+y Treasuries
B15: RK Buy | C15: Corp ST Bond | G15: Emerging SmallCap 1 | I15: France CAC 40 | L15: Aluminum | P15: US Technology | T15: MSCI US Momentum | X15: US Corp Bonds Junk
B16: RK Sell | C16: Corp MT Bond | G16: Emerging SmallCap 2 | I16: Japan Nikkei 225 | L16: Wheat US | P16: computer Software | T16: Cambria Momentum | X16: Japan
B17: Pulse | C17: Corp LT Bond | G17: Europe | I17: Hong King Hang Seng | L17: Corn US | P17: Internet | T17: S&P 500 Value | X17: *Naturl Resources No
... B19: Ind Filter | C19: US Corp | G19: Pacific ex-Japan | I19: Australia ASX 200 | L19: Sugar US | P19: Innovation | T19: S&P 600 Value | X19: Gold Miners
C20: US Corp | G20: BRIC | I20: Canada TSX | L20: Coffee US | P20: China Internet | T20: Russell 1000 Value | X20: Oil WTI
C21: EM Loc | G21: Latin 40 | I21: Energy | L21: Cotton US | P21: Semis | T21: Russell Midcp Value | X21: O&G E&S
G22: Japan | I22: Materials | L22: Cocoa US | P22: Robotics | T22: Russell 2000 Value | X22: Transocean
G23: China | I23: Industrials | L23: Live Cattle | P23: Cyber Security | T23: Towle | X23: Baytex
G24: Brazil | I24: Consumer Discretionary | L24: Lumber | P24: Biotech Nasdaq | T24: O'sh Small | X24: Rare Earths
G25: South Korea | I25: Information Technology | L25: Natural Resources | P25: Biotech General | T25: O'sh Mkt Lds Value | X25: Teck
G26: Taiwan | I26: Health Care | L26: O&G E&P | T26: Hussman Str Growth | X26: Alcoa
X27: Freeport-McMoRan
X28: Sibanye Stillwater
X29: Gooduear
X30: Ryder
X31: Robert Half
X32: Blockchain
X33: Bitcoin
X34: Momentum
X35: Collectors Universe
X36: QQQ
X37: Tesla
X38: Netflix
... X51: Hussman

Sheet Sheet39
A1: Financial Ratio | B1: FY2023 | C1: FY2022 | D1: Formula | E1: Purpose
A2: Liquidity Ratios
A3: Current Ratio | B3: 2.1x | C3: 1.8x | D3: Current Assets / Current Liabilities | E3: Measures the ability to pay short-term obligations with short-term assets
A4: Quick Ratio(Acid-Test Ratio) | B4: 1.5x | C4: 1.3x | D4: (Current Assets - Inventory) / Current Liabilities | E4: Similar to the current ratio but excludes inventory, providing a stricter assessment of liquidity.
A5: Cash Ratio | D5: Formula: Cash + Cash Equivalents/Current Liabilities | E5: Measures the company's ability to cover short-term liabilities with cash and cash equivalents.
A6: Leverage/Solvency Ratios
A7: Interest Coverage Ratio: | D7: Formula: Operating Income/Interest Expense | E7: Purpose: Assesses how easily a company can pay interest on its outstanding debt.
A8: Debt Ratio: | D8: Formula: Total Debt/Total Assets | E8: Purpose: Measures the percentage of assets financed by debt.
A9: Debt to Equity Ratio | B9: 0.6x | C9: 0.7x | D9: Total Debt / Total Equity
A10: Debt Service Coverage Ratio | B10: 1.8x | C10: 1.6x | D10: Net Operating Income / Total Debt Service
A11: Profitability Ratios
A12: Gross Margin | B12: 0.45 | C12: 0.43 | D12: Gross Profit / Revenue
A13: Net Profit Margin | B13: 0.1 | C13: 0.09 | D13: Net Income / Revenue
A14: Efficiency Ratios
A15: Gross Profit Margin: | D15: (Gross Profit/Revenue)×100
A16: Operating Profit Margin: | D16: (Operating Income/Revenue)×100
A17: Net Profit Margin: | D17: (Net Income/Revenue)×100 | E17: Indicates the percentage of revenue that remains as profit after all expenses.
A18: Return on Assets (ROA): | D18: (Net Income/Total Assets)×100 | E18: Measures how effectively a company uses its assets to generate profit.
A19: Return on Equity (ROE): | D19: (Net Income/Shareholder’s Equity)×100 | E19: Indicates the return generated on shareholders' equity.
A20: Efficiency Ratios
A21: Asset Turnover Ratio: | D21: Revenue/Total Assets | E21: Purpose: Shows how efficiently a company uses its assets to generate revenue.
A22: Inventory Turnover Ratio: | D22: Cost of Goods Sold/Average Inventory | E22: Purpose: Indicates how often inventory is sold and replaced over a period.
A23: Receivables Turnover Ratio: | D23: Net Credit Sales/Average Accounts Receivable | E23: Purpose: Measures how efficiently a company collects receivables.
A24: Payables Turnover Ratio: | D24: Cost of Goods Sold/Average Accounts Payable | E24: Formula: Cost of Goods Sold/Average Accounts Payable
A25: CASH FLOWS
A26: Operating Cash Flow (OCF) | D26: Net Income+Non-Cash Expenses+Changes in Working Capital | E26: Purpose: OCF indicates the cash generated by the company’s core business operations. It’s crucial to determine whether a company can generate sufficient cash from its regular operations to sustain its business. | F26: Key Metric: Compare OCF to net income. Ideally, OCF should consistently exceed net income, indicating that earnings are backed by real cash, not just accounting profits. | G26: Consistency: Look for companies with a stable or growing OCF over multiple periods. This suggests strong, recurring cash generation from business operations.
A27: Free Cash Flow (FCF) | D27: Operating Cash Flow−Capital Expenditures | E27: Purpose: FCF is the cash available after capital expenditures (CapEx) and is essential for understanding how much cash the company has to return to shareholders (through dividends or buybacks), reduce debt, or reinvest in the business.
A28: Cash Flow from Investing Activities | D28: Proceeds from Sale of PPE−Purchase of PPE+Proceeds from Sale of Investments−Purchase of Investments±Other Investing Activities | F28: CapEx: High and consistent CapEx may indicate ongoing investments in growth, but it can also consume significant cash. It’s important to assess whether these investments are translating into future revenue and profit growth.Asset Sales: Frequent or significant asset sales could be a red flag, suggesting the company is selling off parts of its business to generate cash.
A29: Cash Flow from Financing Activities | D29: Proceeds from Borrowing−Repayment of Debt+Proceeds from Issuing Stock−Repurchase of Stock−Dividends Paid | E29: Purpose: This section shows cash used in or generated by the company’s investment activities, such as purchasing assets, selling assets, or acquiring other businesses.
A30: Cash Conversion Cycle (CCC) | D30: Days Inventory Outstanding (DIO)+Days Sales Outstanding (DSO)−Days Payable Outstanding (DPO) | E30: Purpose: CCC measures the time it takes for a company to convert its investments in inventory and other resources into cash flows from sales. A shorter CCC indicates efficient management of working capital.
A31: Comparative Analysis | E31: Compare the cash flow metrics of the company with its industry peers. This provides context on whether the company is performing better or worse than its competitors. | F31: Key Insights: Look at industry norms for OCF, FCF, and CapEx intensity. Companies outperforming their peers in these areas may represent solid investment opportunities.
A32: Trend Analysis | E32: Key Metric: A decreasing CCC over time suggests improving efficiency in managing inventory, receivables, and payables. | F32: Key Insights: A company with consistently improving cash flows is generally a better investment candidate than one with erratic or declining cash flows.
A33: Scenario and Sensitivity Analysis | E33: Purpose: Conduct scenario analysis to assess how changes in key assumptions (like revenue growth, margins, or CapEx) impact cash flows. | F33: Key Insights: Sensitivity analysis helps in understanding the robustness of the company’s cash flows under various economic or business conditions.
A34: Stock Market Ratios
A38: Earnings Per Share (EPS):
A40: Formula: Net Income/Number of Outstanding Shares
A41: Purpose: Indicates the portion of a company's profit allocated to each outstanding share of common stock.
A43: Price to Earnings Ratio (P/E Ratio):
A45: Formula: Market Price per Share/Earnings per Share (EPS)
A46: Purpose: Measures the market value per share relative to the earnings per share.
...

Sheet Finding Value
A1: How to approach finding value
A2: Screener
A3: Scour the holdings from the best growth ETFs.
A4: You'll want to narrow the field using financial metrics such as return on assets, earnings per share growth, higher price-to-sales and price-to-cash-flow ratios.
A5: The fund's fact sheet is an excellent place to find basic information such as its top 10 holdings, top sector weightings, and fund characteristics.
A6: learning about the business model, its financial situation and anything else that might influence its share price in the future.
A7: Think like a partner

Sheet Screener
A1: FALSE | B1: ticker | C1: IFTRUE(B1,) | D1: google finance | M1: Technical Analysis | O1: Fundamental | Q1: Basic Info | S1: ?, check RK
A2: INPUT: | B2: GE | D2: change % | E2: =IFERROR(__xludf.DUMMYFUNCTION("GOOGLEFINANCE(B2,""changepct"")"),-1.09) -> -1.09 | M2: Price | O2: revs | Q2: CIK | S2: <1 week
A3: CIK | D3: mkt cap | E3: =IFERROR(__xludf.DUMMYFUNCTION("GOOGLEFINANCE(B2,""marketcap"")"),3.03195451295E11) -> 303195451295 | M3: mkt cap | O3: s/p | Q3: Sector | S3: 1-2w
A4: Sector | D4: %to52w hi | M4: price | O4: ebitda/ev | Q4: company | S4: 2-4w
A5: company | D5: %from52low | M5: daily % change | O5: tb/p | Q5: sector | S5: val
A6: sector | D6: p/e | E6: =IFERROR(__xludf.DUMMYFUNCTION("GOOGLEFINANCE(B2,""pe"")"),38.28) -> 38.28 | M6: % to 52w hi | O6: b/p | Q6: industry | S6: 6m val
A7: industry | D7: e/p | E7: =(1/E6) -> 0.026123302 | M7: % from 52w Lo | O7: e/p | S7: % to val blend
A8: P/e No Growth(0%) | B8: 11 | D8: EPS | E8: =IFERROR(__xludf.DUMMYFUNCTION("GOOGLEFINANCE(B2, ""eps"")"),7.51) -> 7.51 | M8: 52range | O8: cfo/p
A9: Growth Rate???? | B9: 8.5 | D9: data delay | E9: =IFERROR(__xludf.DUMMYFUNCTION("GOOGLEFINANCE(B2,""datadelay"")"),0.0) -> 0 | M9: return1w | O9: sfcf/p
A10: 2 g: | B10: =2*(B9) -> 17 | D10: 52hi | E10: =IFERROR(__xludf.DUMMYFUNCTION("GOOGLEFINANCE(B2,""high52"")"),316.67) -> 316.67 | M10: return4w | O10: ncf/p
A11: Avg Yield AAA bond: | B11: 4.64 | D11: 52lo | E11: =IFERROR(__xludf.DUMMYFUNCTION("GOOGLEFINANCE(B2,""low52"")"),159.36) -> 159.36 | M11: return13w | O11: div/p
A12: Y=Moodys Seasoned AAA | B12: 4.77 | D12: 52range | E12: googlefinance(B2, | M12: return52w | O12: cash/p
B13: =11+17 -> 28 | D13: beta | E13: =IFERROR(__xludf.DUMMYFUNCTION("GOOGLEFINANCE(B2,""beta"")"),1.56) -> 1.56 | M13: return156w | O13: ncash/p
B14: =(B7)*(B8+(2*(B9)))*(B11) -> 0 | D14: shares | E14: =IFERROR(__xludf.DUMMYFUNCTION("GOOGLEFINANCE(B2,""shares"")"),1.054814E9) -> 1054814000 | M14: return260w | O14: nn/p
D15: data delay | E15: =IFERROR(__xludf.DUMMYFUNCTION("GOOGLEFINANCE(B2,""datadelay"")"),0.0) -> 0 | M15: distrib yield | O15: asset/p
D16: close yesterday | E16: =IFERROR(__xludf.DUMMYFUNCTION("GOOGLEFINANCE(B2,""closeyest"")"),290.62) -> 290.62 | M16: ytdreturn | O16: retear/mc
D17: price | E17: =IFERROR(__xludf.DUMMYFUNCTION("GOOGLEFINANCE(B2,""price"")"),287.44) -> 287.44 | O17: revs/debt
O18: mc/ev
O19: Insider Buying
O20: 1m insider buying
O21: 6m insider buying
O22: # of insiders
O23: 65%mos

Sheet Screener beta
B1: scrape on cgi script | C1: data.sec.gov | D1: https://www.sec.gov/cgi-bin/browse-edgar?action=getcurrent | E1: SEC Meetings
B2: Build a Screener Resources | C2: Dividendology Stock Watch search
A5: var index = 1; [].forEach.call(document.getElementsByTagName("table"), function(elements) { console.log("Index: " + index++, elements); }); | B5: Copy and paste the following code into the console to get indexes of all tables:
A6: var index = 1; [].forEach.call(document.querySelectorAll("ul,ol"), function(elements) { console.log("Index: " + index++, elements); }); | B6: If you are looking for all lists’ indexes instead, you need to get all elements with tag <ul> or <ol>. The following code may help you:
A10: =IFERROR(__xludf.DUMMYFUNCTION("IMPORTHTML(""https://finviz.com/quote.ashx?t=EXPR&ty=c&ta=1&p=d"",""table"",""10"")"),"Loading...") -> Loading...
A24: Currency
A25: =IFERROR(__xludf.DUMMYFUNCTION("IMPORTHTML(""https://finance.yahoo.com/currencies"",""table"",1)"),"Loading...") -> Loading...
B54: Stock Ticker | E54: Current Price | G54: =IFERROR(__xludf.DUMMYFUNCTION("SPARKLINE(GOOGLEFINANCE(B56,""price"",today()-700,today()))"),"") | M54: #ERROR!
E55: Volume | M55: =IFERROR(__xludf.DUMMYFUNCTION("IMPORTHTML(""https://www.sec.gov/cgi-bin/browse-edgar?action=getcurrent"",""table"",""7"")"),"Loading...") -> Loading...
B56: AAPL | E56: Day's $ change
E57: Day's % change
E58: 52hi
E59: 52lo
E60: yesterday close
A62: =IFERROR(__xludf.DUMMYFUNCTION("IMPORTHTML(""https://finviz.com/quote.ashx?t=""&B56,""table"",""10"")"),"Loading...") -> Loading...
A75: You can remove the asterisk by using the substitute formula. I use this formula in many of my portfolio trackers. Go back and view some of my portfolio tracker videos to see how I use this.
A79: Ticker | B79: Name | C79: Price | D79: 555 | E79: Day's change | F79: Day's change % | G79: Dividend | H79: 12 month return | I79: Industry
A80: EXPR | B80: =IFERROR(__xludf.DUMMYFUNCTION("GOOGLEFINANCE(A80,""name"")"),"#N/A") -> #N/A | C80: =IFERROR(__xludf.DUMMYFUNCTION("GOOGLEFINANCE(A80,""price"")"),"#N/A") -> #N/A | D80: =IFERROR(__xludf.DUMMYFUNCTION("(SPARKLINE(index(GOOGLEFINANCE(A80,""Price"",today()-$D$79,today()),,2),{""charttype"",""line"";""color"",""purple""}))"),"#N/A") -> #N/A | E80: =IFERROR(__xludf.DUMMYFUNCTION("Googlefinance(A80,""change"")"),"#N/A") -> #N/A | F80: =IFERROR(__xludf.DUMMYFUNCTION("Googlefinance(A80,""changepct"")/100"),"#N/A") -> #N/A | G80: =IFERROR(__xludf.DUMMYFUNCTION("if($A$80="""","""",substitute(SUBSTITUTE(index(importhtml(""http://finviz.com/quote.ashx?t=""&$A$80,""table"",10),7,2),""*"",""""),""-"",""0.00""))"),"Loading...") -> Loading... | H80: =IFERROR(__xludf.DUMMYFUNCTION("(GOOGLEFINANCE(A80,""price"")/index(GOOGLEFINANCE(A2,""price"", datevalue(today()-365)),2,2)-1)"),"#N/A") -> #N/A | I80: =if(O2="","",Left(O2, Search(" |",O2))) | K80: =IFERROR(__xludf.DUMMYFUNCTION("if(A2="""","""",IFERROR(substitute(Index(IMPORTHTML(""https://finviz.com/quote.ashx?t=""&A2,""Table"",8),2,1),""*"",""""),""-""))"),"")
H81: outerHTML | I81: <span class="Fw(600)">Technology</span>
H82: selector | I82: #Col1-0-Profile-Proxy > section > div.asset-profile-container > div > div > p.D\(ib\).Va\(t\) > span:nth-child(2)
H83: xpath | I83: //*[@id="Col1-0-Profile-Proxy"]/section/div[1]/div/div/p[2]/span[2]
A84: What it do? | H84: full. xpath | I84: /html/body/div[1]/div/div/div[1]/div/div[3]/div[1]/div/div[1]/section/div[1]/div/div/p[2]/span[2]
A85: =IFERROR(__xludf.DUMMYFUNCTION("IMPORTHTML(""https://finviz.com/quote.ashx?t=""&A80,""table"",""11"")"),"Loading...") -> Loading... | I85: =IFERROR(__xludf.DUMMYFUNCTION("IMPORTXML(""http://finance.yahoo.com/quote/AAPL/profile?p=AAPL"",""//section/div[1]/div/div/p[2]/span[2]"")"),"#N/A") -> #N/A
E86: =if(O2="","",Left(O2, Search(" |",O2))) | I86: ("//a/@href")
I87: "https://finviz.com/quote.ashx?t="&B56,"table","10")
I88: <div class="quote-links">
I89: <div>
I90: <a href="screener.ashx?v=111&amp;f=sec_consumercyclical" class="tab-link">Consumer Cyclical</a>
I91: <span class="text-muted-3">•</span>
I92: <a href="screener.ashx?v=111&amp;f=ind_apparelretail" class="tab-link">Apparel Retail</a>
I93: <span class="text-muted-3">•</span>
I94: <a href="screener.ashx?v=111&amp;f=geo_usa" class="tab-link">USA</a>
I95: <span class="text-muted-3">•</span>
I96: <a href="screener.ashx?v=111&amp;f=exch_nyse" class="tab-link">NYSE</a>
I97: </div>
I98: <div>
... I110: </div>

Sheet AAA
A1: TICKER | B1: CIK | C1: Company | D1: Index | E1: price | H1: Sector | I1: Industry | J1: 1 | K1: DIVIDEND | L1: mkt cap | M1: Beta | N1: INDEX&MATCH
A2: seci | B2: 925661 | C2: SECTOR 10 Inc | E2: 0.01 | K2: =IFERROR(__xludf.DUMMYFUNCTION("if(A2="""","""",substitute(SUBSTITUTE(index(importhtml(""http://finviz.com/quote.ashx?t=""&A2,""table"",10),7,2),""*"",""""),""-"",""0.00""))"),"Loading...") -> Loading... | L2: 1530 | M2: #N/A
A3: bant | B3: 1704795 | C3: Bantec Inc | E3: 0.01 | K3: =IFERROR(__xludf.DUMMYFUNCTION("if(A3="""","""",substitute(SUBSTITUTE(index(importhtml(""http://finviz.com/quote.ashx?t=""&A3,""table"",10),7,2),""*"",""""),""-"",""0.00""))"),"Loading...") -> Loading... | L3: 48960 | M3: 5.31
A4: unam | B4: 100716 | C4: Unico American Corp | E4: 0.01 | K4: =IFERROR(__xludf.DUMMYFUNCTION("if(A4="""","""",substitute(SUBSTITUTE(index(importhtml(""http://finviz.com/quote.ashx?t=""&A4,""table"",10),7,2),""*"",""""),""-"",""0.00""))"),"Loading...") -> Loading... | L4: 53050 | M4: 0.07
A5: kspn | B5: 795212 | C5: Kaspien Holdings Inc | E5: 0.01 | K5: =IFERROR(__xludf.DUMMYFUNCTION("if(A5="""","""",substitute(SUBSTITUTE(index(importhtml(""http://finviz.com/quote.ashx?t=""&A5,""table"",10),7,2),""*"",""""),""-"",""0.00""))"),"Loading...") -> Loading... | L5: 59640 | M5: 0.51
A6: pssr | B6: 225628 | C6: Passur Aerospace Inc | E6: 0.01 | K6: =IFERROR(__xludf.DUMMYFUNCTION("if(A6="""","""",substitute(SUBSTITUTE(index(importhtml(""http://finviz.com/quote.ashx?t=""&A6,""table"",10),7,2),""*"",""""),""-"",""0.00""))"),"Loading...") -> Loading... | L6: 77120 | M6: #N/A
A7: slch | B7: 1077319 | C7: spotlight Capital Holdings | E7: 0.01 | K7: =IFERROR(__xludf.DUMMYFUNCTION("if(A7="""","""",substitute(SUBSTITUTE(index(importhtml(""http://finviz.com/quote.ashx?t=""&A7,""table"",10),7,2),""*"",""""),""-"",""0.00""))"),"Loading...") -> Loading... | L7: 86810 | M7: 0.59
A8: spowf | B8: 1227282 | C8: Strata Power Corp | E8: 0.01 | K8: =IFERROR(__xludf.DUMMYFUNCTION("if(A8="""","""",substitute(SUBSTITUTE(index(importhtml(""http://finviz.com/quote.ashx?t=""&A8,""table"",10),7,2),""*"",""""),""-"",""0.00""))"),"Loading...") -> Loading... | L8: 120510 | M8: #N/A
A9: bbig | B9: 1717556 | C9: Vinco Ventures Inc | E9: 0.01 | K9: =IFERROR(__xludf.DUMMYFUNCTION("if(A9="""","""",substitute(SUBSTITUTE(index(importhtml(""http://finviz.com/quote.ashx?t=""&A9,""table"",10),7,2),""*"",""""),""-"",""0.00""))"),"Loading...") -> Loading... | L9: 124489 | M9: 0.18
A10: cwnof | B10: 1145898 | C10: Chineseworldnet.Com Inc | E10: 0.01 | K10: =IFERROR(__xludf.DUMMYFUNCTION("if(A10="""","""",substitute(SUBSTITUTE(index(importhtml(""http://finviz.com/quote.ashx?t=""&A10,""table"",10),7,2),""*"",""""),""-"",""0.00""))"),"Loading...") -> Loading... | L10: 124830 | M10: 6.55
A11: rgmp | B11: 1716324 | C11: Regnum Corp | E11: 0.01 | K11: =IFERROR(__xludf.DUMMYFUNCTION("if(A11="""","""",substitute(SUBSTITUTE(index(importhtml(""http://finviz.com/quote.ashx?t=""&A11,""table"",10),7,2),""*"",""""),""-"",""0.00""))"),"Loading...") -> Loading... | L11: 135410 | M11: 6.36
A12: ltryw | B12: 1673481 | C12: Lottery.com | E12: 0.01 | K12: =IFERROR(__xludf.DUMMYFUNCTION("if(A12="""","""",substitute(SUBSTITUTE(index(importhtml(""http://finviz.com/quote.ashx?t=""&A12,""table"",10),7,2),""*"",""""),""-"",""0.00""))"),"#N/A") -> #N/A | L12: 154382 | M12: 4.5
A13: mmnt | B13: 1653876 | C13: Momentous Holdings Corp | E13: 0.01 | K13: =IFERROR(__xludf.DUMMYFUNCTION("if(A13="""","""",substitute(SUBSTITUTE(index(importhtml(""http://finviz.com/quote.ashx?t=""&A13,""table"",10),7,2),""*"",""""),""-"",""0.00""))"),"Loading...") -> Loading... | L13: 168890 | M13: #N/A
A14: fdmsf | B14: 1668987 | C14: Fandifi Technology Corp | E14: 0.01 | K14: =IFERROR(__xludf.DUMMYFUNCTION("if(A14="""","""",substitute(SUBSTITUTE(index(importhtml(""http://finviz.com/quote.ashx?t=""&A14,""table"",10),7,2),""*"",""""),""-"",""0.00""))"),"#N/A") -> #N/A | L14: 205264 | M14: 2.06
A15: gthr | B15: 1017110 | C15: GeneThera Inc | E15: 0.01 | K15: =IFERROR(__xludf.DUMMYFUNCTION("if(A15="""","""",substitute(SUBSTITUTE(index(importhtml(""http://finviz.com/quote.ashx?t=""&A15,""table"",10),7,2),""*"",""""),""-"",""0.00""))"),"Loading...") -> Loading... | L15: 212040 | M15: -0.26
A16: sgmd | B16: 919175 | C16: Sugarmade Inc | E16: 0.01 | K16: =IFERROR(__xludf.DUMMYFUNCTION("if(A16="""","""",substitute(SUBSTITUTE(index(importhtml(""http://finviz.com/quote.ashx?t=""&A16,""table"",10),7,2),""*"",""""),""-"",""0.00""))"),"Loading...") -> Loading... | L16: 230735 | M16: 0.21
A17: wmc | B17: 1465885 | C17: Westmount Minerals Corp | E17: 0.01 | K17: =IFERROR(__xludf.DUMMYFUNCTION("if(A17="""","""",substitute(SUBSTITUTE(index(importhtml(""http://finviz.com/quote.ashx?t=""&A17,""table"",10),7,2),""*"",""""),""-"",""0.00""))"),"Loading...") -> Loading... | L17: 250340 | M17: #N/A
A18: tdrk | B18: 1282496 | C18: Tiderock Companies Inc | E18: 0.01 | K18: =IFERROR(__xludf.DUMMYFUNCTION("if(A18="""","""",substitute(SUBSTITUTE(index(importhtml(""http://finviz.com/quote.ashx?t=""&A18,""table"",10),7,2),""*"",""""),""-"",""0.00""))"),"Loading...") -> Loading... | L18: 263896 | M18: -4.25
A19: blis | B19: 1703625 | C19: Treasure & Shipwreck Recovery Inc | E19: 0.01 | K19: =IFERROR(__xludf.DUMMYFUNCTION("if(A19="""","""",substitute(SUBSTITUTE(index(importhtml(""http://finviz.com/quote.ashx?t=""&A19,""table"",10),7,2),""*"",""""),""-"",""0.00""))"),"Loading...") -> Loading... | L19: 276760 | M19: 49.62
A20: rad | B20: 84129 | C20: Radial Research Corp | E20: 0.01 | K20: =IFERROR(__xludf.DUMMYFUNCTION("if(A20="""","""",substitute(SUBSTITUTE(index(importhtml(""http://finviz.com/quote.ashx?t=""&A20,""table"",10),7,2),""*"",""""),""-"",""0.00""))"),"Loading...") -> Loading... | L20: 278380 | M20: #N/A
A21: apsi | B21: 1553264 | C21: Aqua Power Systems Inc | E21: 0.01 | K21: =IFERROR(__xludf.DUMMYFUNCTION("if(A21="""","""",substitute(SUBSTITUTE(index(importhtml(""http://finviz.com/quote.ashx?t=""&A21,""table"",10),7,2),""*"",""""),""-"",""0.00""))"),"Loading...") -> Loading... | L21: 281868 | M21: 0.7
A22: rahgf | B22: 1611852 | C22: Roan Holdings Group Co Ltd | E22: 0.01 | K22: =IFERROR(__xludf.DUMMYFUNCTION("if(A22="""","""",substitute(SUBSTITUTE(index(importhtml(""http://finviz.com/quote.ashx?t=""&A22,""table"",10),7,2),""*"",""""),""-"",""0.00""))"),"Loading...") -> Loading... | L22: 296370 | M22: -1.71
A23: scps | B23: 1772028 | C23: Scopus Biopharma Inc | E23: 0.01 | K23: =IFERROR(__xludf.DUMMYFUNCTION("if(A23="""","""",substitute(SUBSTITUTE(index(importhtml(""http://finviz.com/quote.ashx?t=""&A23,""table"",10),7,2),""*"",""""),""-"",""0.00""))"),"Loading...") -> Loading... | L23: 315630 | M23: 1.46
A24: sset | B24: 1561686 | C24: Starstream Entertainment Inc | E24: 0.01 | K24: =IFERROR(__xludf.DUMMYFUNCTION("if(A24="""","""",substitute(SUBSTITUTE(index(importhtml(""http://finviz.com/quote.ashx?t=""&A24,""table"",10),7,2),""*"",""""),""-"",""0.00""))"),"Loading...") -> Loading... | L24: 364026 | M24: -0.4
A25: cnbx | B25: 1343009 | C25: CNBX Pharmaceuticals Inc | E25: 0.01 | K25: =IFERROR(__xludf.DUMMYFUNCTION("if(A25="""","""",substitute(SUBSTITUTE(index(importhtml(""http://finviz.com/quote.ashx?t=""&A25,""table"",10),7,2),""*"",""""),""-"",""0.00""))"),"Loading...") -> Loading... | L25: 378107 | M25: 0.68
A26: mgi | B26: 1273931 | C26: Magnum Goldcorp Inc | E26: 0.01 | K26: =IFERROR(__xludf.DUMMYFUNCTION("if(A26="""","""",substitute(SUBSTITUTE(index(importhtml(""http://finviz.com/quote.ashx?t=""&A26,""table"",10),7,2),""*"",""""),""-"",""0.00""))"),"Loading...") -> Loading... | L26: 386200 | M26: -5.5
A27: hgyn | B27: 1324759 | C27: Hong Yuan Holding Group | E27: 0.01 | K27: =IFERROR(__xludf.DUMMYFUNCTION("if(A27="""","""",substitute(SUBSTITUTE(index(importhtml(""http://finviz.com/quote.ashx?t=""&A27,""table"",10),7,2),""*"",""""),""-"",""0.00""))"),"Loading...") -> Loading... | L27: 388128 | M27: 2.58
A28: kmgh | B28: 1471302 | C28: Kemiao Garment Holding Group | E28: 0.01 | K28: =IFERROR(__xludf.DUMMYFUNCTION("if(A28="""","""",substitute(SUBSTITUTE(index(importhtml(""http://finviz.com/quote.ashx?t=""&A28,""table"",10),7,2),""*"",""""),""-"",""0.00""))"),"Loading...") -> Loading... | L28: 404640 | M28: 66.48
A29: ptoi | B29: 1381105 | C29: Plastic2Oil Inc | E29: 0.01 | K29: =IFERROR(__xludf.DUMMYFUNCTION("if(A29="""","""",substitute(SUBSTITUTE(index(importhtml(""http://finviz.com/quote.ashx?t=""&A29,""table"",10),7,2),""*"",""""),""-"",""0.00""))"),"Loading...") -> Loading... | L29: 426914 | M29: -0.06
A30: trirf | B30: 1819876 | C30: Triterras Inc | E30: 0.01 | K30: =IFERROR(__xludf.DUMMYFUNCTION("if(A30="""","""",substitute(SUBSTITUTE(index(importhtml(""http://finviz.com/quote.ashx?t=""&A30,""table"",10),7,2),""*"",""""),""-"",""0.00""))"),"Loading...") -> Loading... | L30: 459144 | M30: 0.86
A31: mccx | B31: 1535079 | C31: MCX Technologies Corp | E31: 0.01 | K31: =IFERROR(__xludf.DUMMYFUNCTION("if(A31="""","""",substitute(SUBSTITUTE(index(importhtml(""http://finviz.com/quote.ashx?t=""&A31,""table"",10),7,2),""*"",""""),""-"",""0.00""))"),"Loading...") -> Loading... | L31: 510650 | M31: #N/A
A32: duuo | B32: 1635136 | C32: Duo World Inc | E32: 0.01 | K32: =IFERROR(__xludf.DUMMYFUNCTION("if(A32="""","""",substitute(SUBSTITUTE(index(importhtml(""http://finviz.com/quote.ashx?t=""&A32,""table"",10),7,2),""*"",""""),""-"",""0.00""))"),"Loading...") -> Loading... | L32: 530260 | M32: 1.05
A33: wddd | B33: 1961 | C33: Worlds Inc | E33: 0.01 | K33: =IFERROR(__xludf.DUMMYFUNCTION("if(A33="""","""",substitute(SUBSTITUTE(index(importhtml(""http://finviz.com/quote.ashx?t=""&A33,""table"",10),7,2),""*"",""""),""-"",""0.00""))"),"Loading...") -> Loading... | L33: 537144 | M33: 0.8
A34: gspt | B34: 1076262 | C34: Super Fresh Foods Inc | E34: 0.01 | K34: =IFERROR(__xludf.DUMMYFUNCTION("if(A34="""","""",substitute(SUBSTITUTE(index(importhtml(""http://finviz.com/quote.ashx?t=""&A34,""table"",10),7,2),""*"",""""),""-"",""0.00""))"),"Loading...") -> Loading... | L34: 573581 | M34: 2.42
A35: crtdw | B35: 1357671 | C35: CREATD | E35: 0.01 | K35: =IFERROR(__xludf.DUMMYFUNCTION("if(A35="""","""",substitute(SUBSTITUTE(index(importhtml(""http://finviz.com/quote.ashx?t=""&A35,""table"",10),7,2),""*"",""""),""-"",""0.00""))"),"Loading...") -> Loading... | L35: 587766 | M35: 4.22
A36: mmmw | B36: 1117228 | C36: Mass Megawatts Inc | E36: 0.01 | K36: =IFERROR(__xludf.DUMMYFUNCTION("if(A36="""","""",substitute(SUBSTITUTE(index(importhtml(""http://finviz.com/quote.ashx?t=""&A36,""table"",10),7,2),""*"",""""),""-"",""0.00""))"),"Loading...") -> Loading... | L36: 629781 | M36: 0.22
A37: revbw | B37: 1810560 | C37: Revelation Biosciences Inc | E37: 0.01 | K37: =IFERROR(__xludf.DUMMYFUNCTION("if(A37="""","""",substitute(SUBSTITUTE(index(importhtml(""http://finviz.com/quote.ashx?t=""&A37,""table"",10),7,2),""*"",""""),""-"",""0.00""))"),"Loading...") -> Loading... | L37: 639181 | M37: 1.88
A38: acmb | B38: 1598323 | C38: Agro Capital Management Corp | E38: 0.01 | K38: =IFERROR(__xludf.DUMMYFUNCTION("if(A38="""","""",substitute(SUBSTITUTE(index(importhtml(""http://finviz.com/quote.ashx?t=""&A38,""table"",10),7,2),""*"",""""),""-"",""0.00""))"),"Loading...") -> Loading... | L38: 658030 | M38: 2.89
A39: nuvi | B39: 1410708 | C39: Emo Capital Corp | E39: 0.01 | K39: =IFERROR(__xludf.DUMMYFUNCTION("if(A39="""","""",substitute(SUBSTITUTE(index(importhtml(""http://finviz.com/quote.ashx?t=""&A39,""table"",10),7,2),""*"",""""),""-"",""0.00""))"),"Loading...") -> Loading... | L39: 672320 | M39: -1.47
A40: mdl | B40: 1370496 | C40: Medallion Resources Ltd | E40: 0.01 | K40: =IFERROR(__xludf.DUMMYFUNCTION("if(A40="""","""",substitute(SUBSTITUTE(index(importhtml(""http://finviz.com/quote.ashx?t=""&A40,""table"",10),7,2),""*"",""""),""-"",""0.00""))"),"Loading...") -> Loading... | L40: 701939 | M40: 1.52
...

Sheet BBB
A1: TICKER | B1: Industry | C1: Sector | D1: IPO | F1: Company Name | G1: MKT CAP | H1: price | I1: Country | J1: Industry | K1: Sector | L1: INDEX | O1: GOAL TO SLIM DOWN LISTINGS
A2: AAPL | B2: Technology | C2: Computer Manufacturing | D2: 1980 | F2: Apple Inc. Common Stock | G2: 2899032972800 | H2: 186.4 | I2: United States | J2: Technology | K2: Computer Manufacturing | L2: NASDAQ
A3: MSFT | B3: Technology | C3: Computer Software: Prepackaged Software | D3: 1986 | F3: Microsoft Corporation Common Stock | G3: 2747484415161 | H3: 369.67 | I3: United States | J3: Technology | K3: Computer Software: Prepackaged Software | L3: NASDAQ
A4: GOOG | B4: Technology | C4: Computer Software: Programming Data Processing | D4: 2004 | F4: Alphabet Inc. Class C Capital Stock | G4: 1677894960000 | H4: 134.06 | I4: United States | J4: Technology | K4: Computer Software: Programming Data Processing | L4: NASDAQ
A5: GOOGL | B5: Technology | C5: Computer Software: Programming Data Processing | D5: 2004 | F5: Alphabet Inc. Class A Common Stock | G5: 1659496440000 | H5: 132.59 | I5: United States | J5: Technology | K5: Computer Software: Programming Data Processing | L5: NASDAQ
A6: AMZN | B6: Consumer Discretionary | C6: Catalog/Specialty Distribution | D6: 1997 | F6: Amazon.com Inc. Common Stock | G6: 1483553430926 | H6: 143.56 | I6: Bermuda | J6: Consumer Discretionary | K6: Catalog/Specialty Distribution | L6: NASDAQ
A7: NVDA | B7: Technology | C7: Semiconductors | D7: 1999 | F7: NVIDIA Corporation Common Stock | G7: 1193874500000 | H7: 483.35 | I7: United States | J7: Technology | K7: Semiconductors | L7: NASDAQ
A8: META | B8: Technology | C8: Computer Software: Programming Data Processing | D8: 2012 | F8: Meta Platforms Inc. Class A Common Stock | G8: 844893770400 | H8: 328.77 | I8: United States | J8: Technology | K8: Computer Software: Programming Data Processing | L8: NASDAQ
A9: BRK/A | F9: Berkshire Hathaway Inc. | G9: 782337288364 | H9: 531886 | I9: United States | L9: NASDAQ
A12: BRK/B | F12: Berkshire Hathaway Inc. | G12: 773444514218 | H12: 350.56 | I12: United States | L12: NYSE
A13: HSBC | B13: Savings Institutions | C13: Finance | F13: HSBC Holdings plc. Common Stock | G13: 729231790000 | H13: 37.03 | I13: United States | J13: Savings Institutions | K13: Finance | L13: NYSE,NASDAQ
A14: HSBC | B14: Finance | C14: Savings Institutions | F14: HSBC Holdings plc. Common Stock | G14: 729231790000 | H14: 37.03 | I14: United States | J14: Finance | K14: Savings Institutions | L14: NASDAQ
A15: TSLA | B15: Consumer Discretionary | C15: Auto Manufacturing | D15: 2010 | F15: Tesla Inc. Common Stock | G15: 682355476578 | H15: 214.65 | I15: Ireland | J15: Consumer Discretionary | K15: Auto Manufacturing | L15: NASDAQ
A16: LLY | B16: Health Care | C16: Biotechnology: Pharmaceutical Preparations | F16: Eli Lilly and Company Common Stock | G16: 567410428627 | H16: 597.71 | I16: United States | J16: Health Care | K16: Biotechnology: Pharmaceutical Preparations | L16: NASDAQ
A17: LLY | B17: Biotechnology: Pharmaceutical Preparations | C17: Health Care | F17: Eli Lilly and Company Common Stock | G17: 567410428627 | H17: 597.71 | I17: United States | J17: Biotechnology: Pharmaceutical Preparations | K17: Health Care | L17: NYSE
A18: TSM | B18: Technology | C18: Semiconductors | D18: 1997 | F18: Taiwan Semiconductor Manufacturing Company Ltd. | G18: 505331254404 | H18: 97.44 | I18: United States | J18: Technology | K18: Semiconductors | L18: NASDAQ
A19: TSM | B19: Semiconductors | C19: Technology | D19: 1997 | F19: Taiwan Semiconductor Manufacturing Company Ltd. | G19: 505331254404 | H19: 97.44 | I19: United States | J19: Semiconductors | K19: Technology | L19: NYSE
A20: UNH | B20: Medical Specialities | C20: Health Care | F20: UnitedHealth Group Incorporated Common Stock (DE) | G20: 500578817825 | H20: 541.21 | I20: United States | J20: Medical Specialities | K20: Health Care | L20: NYSE
A21: UNH | B21: Health Care | C21: Medical Specialities | F21: UnitedHealth Group Incorporated Common Stock (DE) | G21: 500578817825 | H21: 541.21 | I21: United States | J21: Health Care | K21: Medical Specialities | L21: NASDAQ
A22: V | B22: Consumer Discretionary | C22: Business Services | F22: Visa Inc. | G22: 456616403717 | H22: 245.25 | I22: Israel | J22: Consumer Discretionary | K22: Business Services | L22: NASDAQ
A23: V | B23: Business Services | C23: Consumer Discretionary | F23: Visa Inc. | G23: 456616403717 | H23: 245.25 | I23: United States | J23: Business Services | K23: Consumer Discretionary | L23: NYSE
A24: NVO | B24: Health Care | C24: Biotechnology: Biological Products (No Diagnostic Substances) | F24: Novo Nordisk A/S Common Stock | G24: 453124941994 | H24: 101.19 | I24: United States | J24: Health Care | K24: Biotechnology: Biological Products (No Diagnostic Substances) | L24: NASDAQ
A25: NVO | B25: Biotechnology: Biological Products (No Diagnostic Substances) | C25: Health Care | F25: Novo Nordisk A/S Common Stock | G25: 453124941994 | H25: 101.19 | I25: United States | J25: Biotechnology: Biological Products (No Diagnostic Substances) | K25: Health Care | L25: NYSE
A26: WMT | B26: Consumer Discretionary | C26: Department/Specialty Retail Stores | F26: Walmart Inc. Common Stock | G26: 447310996232 | H26: 166.19 | I26: Israel | J26: Consumer Discretionary | K26: Department/Specialty Retail Stores | L26: NASDAQ
A27: WMT | B27: Department/Specialty Retail Stores | C27: Consumer Discretionary | F27: Walmart Inc. Common Stock | G27: 447310996232 | H27: 166.19 | I27: United States | J27: Department/Specialty Retail Stores | K27: Consumer Discretionary | L27: NYSE
A28: SHEL | B28: Energy | C28: Oil & Gas Production | D28: 2022 | F28: Shell PLC American Depositary Shares (each representing two (2) Ordinary Shares) | G28: 438904081600 | H28: 65.6 | I28: South Korea | J28: Energy | K28: Oil & Gas Production | L28: NASDAQ
A29: SHEL | B29: Oil & Gas Production | C29: Energy | D29: 2022 | F29: Shell PLC American Depositary Shares (each representing two (2) Ordinary Shares) | G29: 438904081600 | H29: 65.6 | I29: United States | J29: Oil & Gas Production | K29: Energy | L29: NYSE
A30: JPM | B30: Major Banks | C30: Finance | F30: JP Morgan Chase & Co. Common Stock | G30: 423330351373 | H30: 146.43 | I30: United States | J30: Major Banks | K30: Finance | L30: NYSE
A31: JPM | B31: Finance | C31: Major Banks | F31: JP Morgan Chase & Co. Common Stock | G31: 423330351373 | H31: 146.43 | I31: United States | J31: Finance | K31: Major Banks | L31: NASDAQ
A32: XOM | B32: Energy | C32: Integrated oil Companies | F32: Exxon Mobil Corporation Common Stock | G32: 411152730673 | H32: 103.75 | I32: Switzerland | J32: Energy | K32: Integrated oil Companies | L32: NASDAQ
A33: XOM | B33: Integrated oil Companies | C33: Energy | F33: Exxon Mobil Corporation Common Stock | G33: 411152730673 | H33: 103.75 | I33: United States | J33: Integrated oil Companies | K33: Energy | L33: NYSE
A34: AVGO | B34: Technology | C34: Semiconductors | D34: 2009 | F34: Broadcom Inc. Common Stock | G34: 395202499790 | H34: 957.52 | I34: United States | J34: Technology | K34: Semiconductors | L34: NASDAQ
A35: MA | B35: Consumer Discretionary | C35: Business Services | D35: 2006 | F35: Mastercard Incorporated Common Stock | G35: 369840122937 | H35: 394.38 | I35: China | J35: Consumer Discretionary | K35: Business Services | L35: NASDAQ
A36: MA | B36: Business Services | C36: Consumer Discretionary | D36: 2006 | F36: Mastercard Incorporated Common Stock | G36: 369840122937 | H36: 394.38 | I36: United States | J36: Business Services | K36: Consumer Discretionary | L36: NYSE
A37: PG | B37: Consumer Discretionary | C37: Package Goods/Cosmetics | F37: Procter & Gamble Company (The) Common Stock | G37: 356856141208 | H37: 151.41 | I37: China | J37: Consumer Discretionary | K37: Package Goods/Cosmetics | L37: NASDAQ
A38: PG | B38: Package Goods/Cosmetics | C38: Consumer Discretionary | F38: Procter & Gamble Company (The) Common Stock | G38: 356856141208 | H38: 151.41 | I38: United States | J38: Package Goods/Cosmetics | K38: Consumer Discretionary | L38: NYSE
A39: JNJ | B39: Health Care | C39: Biotechnology: Pharmaceutical Preparations | F39: Johnson & Johnson Common Stock | G39: 354471776795 | H39: 147.25 | I39: United States | J39: Health Care | K39: Biotechnology: Pharmaceutical Preparations | L39: NASDAQ
A40: JNJ | B40: Biotechnology: Pharmaceutical Preparations | C40: Health Care | F40: Johnson & Johnson Common Stock | G40: 354471776795 | H40: 147.25 | I40: United States | J40: Biotechnology: Pharmaceutical Preparations | K40: Health Care | L40: NYSE
A41: ORCL | B41: Technology | C41: Computer Software: Prepackaged Software | D41: 1986 | F41: Oracle Corporation Common Stock | G41: 309791560470 | H41: 113.07 | I41: United States | J41: Technology | K41: Computer Software: Prepackaged Software | L41: NASDAQ
A42: ORCL | B42: Computer Software: Prepackaged Software | C42: Technology | D42: 1986 | F42: Oracle Corporation Common Stock | G42: 309791560470 | H42: 113.07 | I42: United States | J42: Computer Software: Prepackaged Software | K42: Technology | L42: NYSE
...

Sheet CCC
A1: TICKER | B1: Industry | C1: Sector
G2: Computer Manufacturing
G3: Computer Software: Prepackaged Software
A4: BRK/A | G4: Computer Software: Programming Data Processing
A5: AAPL | B5: Computer Manufacturing | C5: Technology | G5: Computer Software: Programming Data Processing
A6: MSFT | B6: Computer Software: Prepackaged Software | C6: Technology | G6: Catalog/Specialty Distribution
A7: GOOG | B7: Computer Software: Programming Data Processing | C7: Technology | G7: Semiconductors
A8: GOOGL | B8: Computer Software: Programming Data Processing | C8: Technology | G8: Computer Software: Programming Data Processing
A9: AMZN | B9: Catalog/Specialty Distribution | C9: Consumer Discretionary
A10: NVDA | B10: Semiconductors | C10: Technology
A11: META | B11: Computer Software: Programming Data Processing | C11: Technology
A12: BRK/B
A13: HSBC | B13: Savings Institutions | C13: Finance
A14: HSBC | B14: Finance | C14: Savings Institutions
A15: TSLA | B15: Consumer Discretionary | C15: Auto Manufacturing
A16: LLY | B16: Health Care | C16: Biotechnology: Pharmaceutical Preparations
A17: LLY | B17: Biotechnology: Pharmaceutical Preparations | C17: Health Care
A18: TSM | B18: Technology | C18: Semiconductors
A19: TSM | B19: Semiconductors | C19: Technology
A20: UNH | B20: Medical Specialities | C20: Health Care
A21: UNH | B21: Health Care | C21: Medical Specialities
A22: V | B22: Consumer Discretionary | C22: Business Services
A23: V | B23: Business Services | C23: Consumer Discretionary
A24: NVO | B24: Health Care | C24: Biotechnology: Biological Products (No Diagnostic Substances)
... A139: RTX | B139: Aerospace | C139: Industrials
A140: RY
A141: RY
A142: UPS | B142: Trucking Freight/Courier Services | C142: Industrials
A143: UPS | B143: Industrials | C143: Trucking Freight/Courier Services
A144: SNY | B144: Health Care | C144: Biotechnology: Pharmaceutical Preparations
A145: NEE | B145: Utilities | C145: Electric Utilities: Central
A146: NEE | B146: Electric Utilities: Central | C146: Utilities
A147: AXP | B147: Finance | C147: Finance: Consumer Services
A148: AXP | B148: Finance: Consumer Services | C148: Finance
A149: LOW | B149: Consumer Discretionary | C149: RETAIL: Building Materials
A150: LOW | B150: RETAIL: Building Materials | C150: Consumer Discretionary
A151: T | B151: Telecommunications Equipment | C151: Telecommunications
A152: T | B152: Telecommunications | C152: Telecommunications Equipment
A153: LMT | B153: Military/Government/Technical | C153: Industrials
A154: LMT | B154: Industrials | C154: Military/Government/Technical
...

Sheet Watchlist
A1: dm | B1: 3d
A2: ssys | B2: 3d
A3: ddd
A4: frd
A5: vir
A6: pbf
D101: \

Sheet Altman Z
A1: Brand Equity | B1: 12 Months Ended | M1: EXPRESS | N1: Altman Z-score | O1: "Z-Score" model is a numerical measurement that is used to predict the chances of a business becoming bankrupt in the next two years.
B2: 44954 | C2: 44982 | D2: 44772 | M2: 10-k, 1/28/23 | O2: The formula takes into account profitability, leverage, liquidity, solvency, and activity ratios.
A3: Cover [Abstract] | M3: Steps: 1 | N3: working capital= | O3: Current Assets − Current Liabilities | Q3: 534404000 | R3: 1090756000 | S3: =Q3-R3 -> -556352000 | T3: Working capital is a measure of a company's operational liquidity and short-term financial health.
A4: Document Type | B4: 10-K | M4: 2 | N4: Retained Earnings= | O4: Begin Retained Earnings+NI−Dividends | S4: 355736000 | T4: Retained earnings=leftover profit after paying all its direct/indirect costs, taxes & dividends
A5: Document Annual Report | B5: TRUE | G5: working cap | H5: working cap | M5: 3 | N5: EBIT= Operating income = | O5: gross profit - OpEx | Q5: 528594000 | R5: 596081000 | S5: =Q5-R5 -> -67487000 | T5: represents the point on the income statement where all operating costs have been deducted.
A6: Document Period End Date | B6: 44954 | F6: Question | G6: 10-k january | H6: 10q october | M6: 4 | N6: Market Value of Equity(mktcap)= | O6: share price * # Outstanding Shares | Q6: 7.45 | R6: 73761930 | S6: =Q6*R6 -> 5.4952638e+08 | T6: Shows the degree to which a company’s market value would decline when it declares bankruptcy before the value of liabilities exceeds the value of assets on the balance sheet.
A7: Current Fiscal Year End Date | B7: --01-28 | M7: 5 | N7: Current Assets/Liab(-)= | O7: found on balance sheet = | Q7: 598879000 | S7: 613068000 | T7: A high market value of equity to total liabilities ratio can be interpreted to mean high investor confidence in the company’s financial strength.
A8: Document Transition Report | B8: FALSE | N8: Total Assets/Liab(-)= | O8: found on balance sheet = | Q8: 1398325000 | S8: 1090756000 | T8: current assets (liabilities) = liquid assets that can be sold (received) within a year
A9: Entity File Number | B9: 001-34742 | N9: Sales(net sales or rev) | O9: found on balance sheet = | Q9: 1864182000 | T9: Book Value=Total Assets−Total Liabilities
A10: Entity Registrant Name | B10: EXPRESS, INC. | N10: Altman Z-Score = | O10: 1.2ₓ₁ + 1.4ₓ₂ + 3.3ₓ₃ + 0.6ₓ₄ + 1.0ₓ₅
A11: Entity Incorporation, State or Country Code | B11: DE
A12: Entity Tax Identification Number | B12: 26-2828128 | N12: x1= | O12: =S3 -> -556352000 | P12: / | Q12: =Q8 -> 1398325000 | R12: =O12/Q12 -> -0.39787031 | T12: X1 = Working Capital / Total Assets (measures liquidity)
A13: Entity Address, Address Line One | B13: 1 Express Drive | N13: x2= | O13: =S4 -> 355736000 | P13: / | Q13: =Q8 -> 1398325000 | R13: =O13/Q13 -> 0.25440152 | T13: X2 = Retained Earnings / Total Assets
A14: Entity Address, City or Town | B14: Columbus | N14: x3= | O14: =S5 -> -67487000 | P14: / | Q14: =Q8 -> 1398325000 | R14: =O14/Q14 -> -0.048262743 | T14: X3 = Earnings Before Tax and Interest (OI)/ Total Assets (measures how effectively the company uses its assets to get return)
A15: Entity Address, State or Province | B15: OH | N15: x4= | O15: =S6 -> 5.4952638e+08 | P15: / | Q15: =S8 -> 1090756000 | R15: =O15/Q15 -> 0.50380321 | T15: X4 = Market Value of Equity / Total Liabilities (measures the market’s view of the company’s health)
A16: Entity Address, Postal Zip Code | B16: 43230 | N16: x5= | O16: =Q9 -> 1864182000 | P16: / | Q16: =Q8 -> 1398325000 | R16: =O16/Q16 -> 1.3331536 | T16: X5 = Sales / Total Assets (indicated asset turnover)
A17: City Area Code | B17: 614 | G17: Z= | H17: 1.2(
A18: Local Phone Number | B18: 474-4001 | N18: ζ₁= | O18: 1.2 X1 + 1.4 X2 + 3.3 X3 + 0.6 X4 + 1.0 X5 | Q18: = | R18: =SUM(R12:R16) -> 1.6452253 | X18: NYU Stern's Altman Z-score formula in 1967, and it was published in 1968. Over the years, Altman has continued to reevaluate his Z-score. From 1969-1975, Altman looked at 86 companies in distress, then 110 from 1976 to 1995, and finally 120 from 1996 to 1999, finding that the Z-score had an accuracy of between 82% and 94%.
A19: Title of 12(b) Security | B19: Common Stock, $.01 par value
A20: Trading Symbol | B20: EXPR | T20: The formula takes into account profitability, leverage, liquidity, solvency, and activity ratios.
A21: Security Exchange Name | B21: NYSE | T21: Score below 1.8: Suggests a higher risk of financial distress and potential bankruptcy.
A22: Entity Well-known Seasoned Issuer | B22: No | T22: close to 0 suggests a company might be headed for bankruptcy.
A23: Entity Voluntary Filers | B23: No | T23: A score closer to 3 suggests a company is in solid financial positioning
A24: Entity Current Reporting Status | B24: Yes
A25: Entity Interactive Data Current | B25: Yes
A26: Entity Filer Category | B26: Accelerated Filer
A27: Entity Small Business | B27: FALSE | G27: A is the working capital / total assets ratio.
A28: Entity Emerging Growth Company | B28: FALSE | G28: B is the retained earnings / total assets ratio.
A29: ICFR Auditor Attestation Flag | B29: TRUE | G29: C is the earnings before interest and taxes (EBIT) / total assets ratio.
A30: Entity Shell Company | B30: FALSE | G30: D is the market value of equity / total liabilities ratio.
A31: Entity Public Float | D31: 111275008 | G31: E is the sales / total assets ratio.
A32: Entity Common Stock, Shares Outstanding | C32: 73761930
A33: Documents Incorporated by Reference | B33: Certain portions of the registrant's definitive Proxy Statement for its 2023 A
A34: Entity Central Index Key | B34: 1483510
A35: Document Fiscal Year Focus | B35: 2022
A36: Document Fiscal Period Focus | B36: FY
A37: Amendment Flag | B37: FALSE
A38: Audit Information | B38: 12 Months Ended
B39: 44954 | M39: 1. Working Capital/Total Assets
A40: Audit Information [Abstract] | M40: Working capital is the difference between the current assets of a company and its current liabilities. The value of a company’s working capital determines its short-term financial health. A positive working capital means that a company can meet its short-term financial obligations and still make funds available to invest and grow.
...

Sheet Library
A1: Terminology | E1: random jargon | F1: BOOKS & ARTICLES | G1: coding | H1: HELP
A2: (STM) | E2: Software as a service (SaaS) | F2: Secrets of Successful Traders | G2: web server machine | H2: Simple way to select and edit range
A3: *Revenues Avg3 | E3: INTERPOL wanted list | H3: formula help
A4: 5 C's of Credit | E4: b2b marketing
A5: Absolute return | E5: p2p
A6: Accounts Receivabe >90%ile | E6: chimerical,
A7: accruals | E7: heuristics
A8: Accumulated Depreciation | E8: Complex adaptive systems
A9: Accumulated Other Comprehensive Income (AOCI) | E9: non-linearity
A10: Acid Test Ratio | E10: linear regression
A11: Actionable | E11: decile
A12: Activity-Based Costing | E12: illusory
A13: Adjusted Gross Income | E13: diversity loss
A14: Altman Z' Score | E14: apophenia
A15: Altman Z'' Score | E15: breadth
... A19: Asset Quality Index (AQI) | E19: econometrics
A20: Assets
A21: Assets Revaluation
A22: Assets/sh
A23: Assumptions/Drivers of a Financial Model
A24: Available Core Funding (ACF)
A25: Average inventory
A26: Avg Yield of AAA Corp Bonds
A27: b/p
A28: Balance Sheet LHS
A29: Barriers to entry
A30: base rates
A31: Beachhead
... A291: Net Operating Income (NOI)
A292: Net Present Value (NPV) | F292: DSCR = Net Operating Income/Total Debt Service | H292: NOI | I292: TDS (NetInt-PrincipalPayments)
A293: Net Sales | G293: Operating Revs - Operating Exp | H293: =G294-G295 -> 1268101000 | I293: -1254000000 | J293: =H293/I293 -> -1.0112448
A294: Net Sales | F294: Op Rev | G294: 1864182000
A295: Net-Net /sh | F295: Op Exp | G295: 596081000
A296: Next Twelve Months (NTM)
A297: nn/p | G297: Net Interest Expense | H297: -29103000
A298: Non-Common Equities | G298: Principle Payments | H298: -96737000
A299: Non-Current (Long-Term) Liabilities | H299: =sum(H297+H298) -> -125840000
A300: non-linear financials
A301: Non-Operating Cost
A302: Normalized EBITDA
...

Sheet A-Z
A1: Questions to ask about why to buy or sell a stock
A2: Interrogative determiners: Who what where why when can will | E2: 1. Screening Requirements
A3: Bond info | E3: 2. Holding Requirements
A4: quickly see the company’s historical return on equity. | E4: 3. Selling Requirements
A5: I wanted to quickly see how these numbers compare to the other companies in the industry. | E5: -Think about adding data about insiders CEO quality etc
A6: if their profit margin was growing | E6: -Catalysts
A7: show me whether the company can make its debt payments. | E7: -Integrate API
A8: if the stock is undervalued based on a detailed discounted cash flow valuation. | E8: -Intregrate Scrapes
A9: Is the current P/E ratio of 96.82 high or low relative to other online retailers?(AMZN) | E9: -Integrate cashtag mentions from WSB, X etc.
A10: Is it high or low compared to the market average?
A11: Is it high or low compared to 2 years ago?
A12: when is a company with negative earnings a good investnment
A13: Is a stock repurchase ever a bad thing?
A14: Track record of board members, years
A15: How do I figure out the debt payment requirements for a public company
A16: What all should I screen for when choosing companies to invest in?
A17: How has Marks(Oaktree Cap) and his team have generated market-beating returns for decades, mainly by value investing in distressed debt and controlling risks.
A18: Make a tracker that analyzes and charts how a stock tends to move after a particular individual buys the stock.
A19: What does it mean to "buy low"?
A20: Firm is in stable growth; grows at constant rate forever. Domoradan?
A21: OK so lets say there are two companies that enter a strategic parthernship The first company invests 23 million dollars into the second company. The first company receives 5.4 million shares of the second company. the second company has good cash flows but has high debt levels. who got a better deal in this scenario?
... A101: What conditions would mean the federal reserve is not tight enough?

Sheet Data Engineering
A1: Extract, Transform, Load (ETL) | C1: How can you parallelize predictive modeling for big data analytics? | I1: What are irrelevant or redundant features?
A2: Lakehouses | C2: Great use of Figma/PowerPoint background template for rounded edges. | I2: Why remove irrelevant or redundant features?
A3: DataWeave (dw) Format | I3: How to identify irrelevant or redundant features?
A4: XML | I4: How to evaluate the impact of removing irrelevant or redundant features?
A5: A/B testing | I5: Here’s what else to consider
A6: Database Management Systems (DBMS)
A7: DataOps | I7: You want to be able to analyze the data with a multi-cloud data tool that is inexpensive, fast, and does not create additional overhead of decentralized data governance. By using BigQuery Omni, we reduce these frictions with a unified interface.
A8: data engineering
A9: Hard Skills vs Soft Skills
A10: Causal Inference
A11: pedagogy
A12: Third Normal Form
A13: ERP
A14: siloed
A15: SDK
A16: DML statements

Sheet Valuation
A1: Graham's Valuation | B1: A Stock-Picker’s Guide to Benjamin Graham’s Screening Rules | E1: V = EPS x (8.5 + 2g) x 4.4 / Y | I1: shares in millions instead of thousands15552752000000 | K1: =8.5+17 -> 25.5
A2: Ticker | B2: expr | G2: 1000000
A3: P/e ttm? | B3: =IFERROR(__xludf.DUMMYFUNCTION("GOOGLEFINANCE(B2,""pe"")"),"#N/A") -> #N/A | D3: current price | E3: =IFERROR(__xludf.DUMMYFUNCTION("GOOGLEFINANCE(B2,""price"")"),"#N/A") -> #N/A | F3: latest earnings(net income) | G3: 96995000000 | H3: latest OS #: | I3: 15552752000
A4: Earnings Yield (e/p) | B4: =1/B3 -> #N/A
A5: EPS google finance | B5: =IFERROR(__xludf.DUMMYFUNCTION("GOOGLEFINANCE(B2, ""eps"")"),"#N/A") -> #N/A | G5: EPS | H5: =G3/I3 -> 6.2365169 | J5: V= | K5: =K4/4.77 -> 0
A6: P/e No Growth(0%) | B6: 8.5 | G6: P/e | H6: =E3/H5 -> #N/A
A7: Growth Rate???? | B7: 8.5 | E7: 50.3*17*4.4 | F7: %🔺 Current price/intrinsic value
A8: 2 g: | B8: =2*(B7) -> 17 | G8: Buy or Sell: | H8: =If(H7>H4,"Buy","Sell") -> Sell
A9: Avg Yield AAA bond: | B9: 4.64
A10: Y=Moodys Seasoned AAA | B10: 4.77
B11: =11+17 -> 28
A12: EPS*(P/e(nogrowth=8.5)*2g)*Avg Yield AA | B12: =(B5)*(B6+B8)*(B9) -> #N/A
A13: V, Intrinsic Value= | B13: =B12/B10 -> #N/A | E13: Asmoradan Advanced Valuation Ratios
A14: Stock Price | B14: =IFERROR(__xludf.DUMMYFUNCTION("GOOGLEFINANCE(B2,""price"")"),"#N/A") -> #N/A
A15: %🔺 Current price/intrinsic value | B15: =B14/B13 -> #N/A
A16: Margin of Safety(65%)Acceptable buy price | B16: =B13*0.65 -> #N/A
A17: Buy or Sell: | B17: =If(B16>B13,"Buy","Sell") -> #N/A
A19: GRahams REvised Valuation formula
A21: 1 | B21: In finance, valuation is the process of determining the value of a (potential) investment, asset, or security. Generally, there are three approaches taken, namely discounted cashflow valuation, relative valuation, and contingent claim valuation.[1] Valuations can be done for assets (for example, investments in marketable securities such as companies' shares and related rights, business enterprises, or intangible assets such as patents, data and trademarks) or for liabilities (e.g., bonds issued by a company). Valuation is a subjective exercise, and in fact, the process of valuation itself can also affect the value of the asset in question. Valuations may be needed for various reasons such as investment analysis, capital budgeting, merger and acquisition transactions, financial reporting, taxable events to determine the proper tax liability. In a business valuation context, various techniques are used to determine the (hypothetical) price that a third party would pay for a given company; while in a portfolio management context, stock valuation is used by analysts to determine the price at which the stock is fairly valued relative to its projected and historical earnings, and to thus profit from related price movement.
A22: 2 | B22: Valuation overview Common terms for the value of an asset or liability are market value, fair value, and intrinsic value. The meanings of these terms differ. For instance, when an analyst believes a stock's intrinsic value is greater (or less) than its market price, an analyst makes a "buy" (or "sell") recommendation. Moreover, an asset's intrinsic value may be subject to personal opinion and vary among analysts. The International Valuation Standards include definitions for common bases of value and generally accepted practice procedures for valuing assets of all types. Regardless, the valuation itself is done generally using one or more of the following approaches;[2] but see also, Outline of finance § Valuation: Absolute value models ("Intrinsic valuation") that determine the present value of an asset's expected future cash flows. These models take two general forms: multi-period models such as discounted cash flow models, or single-period models such as the Gordon model (which, in fact, often "telescope" the former). These models rely on mathematics rather than price observation. See § Discounted cash flow valuation there. Relative value models determine value based on the observation of market prices of 'comparable' assets, relative to a common variable like earnings, cashflows, book value or sales. This result will often be used to complement / revisit the intrinsic valuation. See § Relative valuation there. Option pricing models, in this context, are used to value specific balance-sheet items, or the asset itself, when these have option-like characteristics. Examples of the first type are warrants, employee stock options, and investments with embedded options such as callable bonds; the second type are usually real options. The most common option pricing models employed here are the Black–Scholes-Merton models and lattice models. This approach is sometimes referred to as contingent claim valuation, in that the value will be contingent on some other asset; see § Contingent claim valuation there.
